[2023-08-07T04:36:30.666+0000] {taskinstance.py:1103} INFO - Dependencies all met for dep_context=non-requeueable deps ti=<TaskInstance: perform_s3_tasks.load_files_into_bucket manual__2023-08-07T04:36:09.870769+00:00 [queued]>
[2023-08-07T04:36:30.720+0000] {taskinstance.py:1103} INFO - Dependencies all met for dep_context=requeueable deps ti=<TaskInstance: perform_s3_tasks.load_files_into_bucket manual__2023-08-07T04:36:09.870769+00:00 [queued]>
[2023-08-07T04:36:30.721+0000] {taskinstance.py:1308} INFO - Starting attempt 1 of 6
[2023-08-07T04:36:31.143+0000] {taskinstance.py:1327} INFO - Executing <Task(LocalFilesystemToS3Operator): load_files_into_bucket> on 2023-08-07 04:36:09.870769+00:00
[2023-08-07T04:36:31.214+0000] {standard_task_runner.py:57} INFO - Started process 236 to run task
[2023-08-07T04:36:31.260+0000] {standard_task_runner.py:84} INFO - Running: ['***', 'tasks', 'run', 'perform_s3_tasks', 'load_files_into_bucket', 'manual__2023-08-07T04:36:09.870769+00:00', '--job-id', '7', '--raw', '--subdir', 'DAGS_FOLDER/s3_dag.py', '--cfg-path', '/tmp/tmp2vf4vp4n']
[2023-08-07T04:36:31.292+0000] {standard_task_runner.py:85} INFO - Job 7: Subtask load_files_into_bucket
[2023-08-07T04:36:31.629+0000] {task_command.py:410} INFO - Running <TaskInstance: perform_s3_tasks.load_files_into_bucket manual__2023-08-07T04:36:09.870769+00:00 [running]> on host 95071573e7de
[2023-08-07T04:36:32.366+0000] {taskinstance.py:1547} INFO - Exporting env vars: AIRFLOW_CTX_DAG_OWNER='abhi' AIRFLOW_CTX_DAG_ID='perform_s3_tasks' AIRFLOW_CTX_TASK_ID='load_files_into_bucket' AIRFLOW_CTX_EXECUTION_DATE='2023-08-07T04:36:09.870769+00:00' AIRFLOW_CTX_TRY_NUMBER='1' AIRFLOW_CTX_DAG_RUN_ID='manual__2023-08-07T04:36:09.870769+00:00'
[2023-08-07T04:36:32.422+0000] {base.py:73} INFO - Using connection ID 's3_conn' for task execution.
[2023-08-07T04:36:32.426+0000] {connection_wrapper.py:337} INFO - AWS Connection (conn_id='s3_conn', conn_type='aws') credentials retrieved from login and password.
[2023-08-07T04:36:36.992+0000] {taskinstance.py:1824} ERROR - Task failed with exception
Traceback (most recent call last):
  File "/home/airflow/.local/lib/python3.7/site-packages/airflow/providers/amazon/aws/transfers/local_to_s3.py", line 107, in execute
    self.acl_policy,
  File "/home/airflow/.local/lib/python3.7/site-packages/airflow/providers/amazon/aws/hooks/s3.py", line 115, in wrapper
    return func(*bound_args.args, **bound_args.kwargs)
  File "/home/airflow/.local/lib/python3.7/site-packages/airflow/providers/amazon/aws/hooks/s3.py", line 86, in wrapper
    return func(*bound_args.args, **bound_args.kwargs)
  File "/home/airflow/.local/lib/python3.7/site-packages/airflow/providers/amazon/aws/hooks/s3.py", line 680, in load_file
    if not replace and self.check_for_key(key, bucket_name):
  File "/home/airflow/.local/lib/python3.7/site-packages/airflow/providers/amazon/aws/hooks/s3.py", line 115, in wrapper
    return func(*bound_args.args, **bound_args.kwargs)
  File "/home/airflow/.local/lib/python3.7/site-packages/airflow/providers/amazon/aws/hooks/s3.py", line 86, in wrapper
    return func(*bound_args.args, **bound_args.kwargs)
  File "/home/airflow/.local/lib/python3.7/site-packages/airflow/providers/amazon/aws/hooks/s3.py", line 523, in check_for_key
    obj = self.head_object(key, bucket_name)
  File "/home/airflow/.local/lib/python3.7/site-packages/airflow/providers/amazon/aws/hooks/s3.py", line 115, in wrapper
    return func(*bound_args.args, **bound_args.kwargs)
  File "/home/airflow/.local/lib/python3.7/site-packages/airflow/providers/amazon/aws/hooks/s3.py", line 86, in wrapper
    return func(*bound_args.args, **bound_args.kwargs)
  File "/home/airflow/.local/lib/python3.7/site-packages/airflow/providers/amazon/aws/hooks/s3.py", line 503, in head_object
    return self.get_conn().head_object(Bucket=bucket_name, Key=key)
  File "/home/airflow/.local/lib/python3.7/site-packages/botocore/client.py", line 530, in _api_call
    return self._make_api_call(operation_name, kwargs)
  File "/home/airflow/.local/lib/python3.7/site-packages/botocore/client.py", line 928, in _make_api_call
    headers=additional_headers,
  File "/home/airflow/.local/lib/python3.7/site-packages/botocore/client.py", line 992, in _convert_to_request_dict
    api_params, operation_model
  File "/home/airflow/.local/lib/python3.7/site-packages/botocore/validate.py", line 381, in serialize_to_request
    raise ParamValidationError(report=report.generate_report())
botocore.exceptions.ParamValidationError: Parameter validation failed:
Invalid length for parameter Key, value: 0, valid min length: 1
[2023-08-07T04:36:37.040+0000] {taskinstance.py:1350} INFO - Marking task as UP_FOR_RETRY. dag_id=perform_s3_tasks, task_id=load_files_into_bucket, execution_date=20230807T043609, start_date=20230807T043630, end_date=20230807T043637
[2023-08-07T04:36:37.074+0000] {standard_task_runner.py:109} ERROR - Failed to execute job 7 for task load_files_into_bucket (Parameter validation failed:
Invalid length for parameter Key, value: 0, valid min length: 1; 236)
[2023-08-07T04:36:37.134+0000] {local_task_job_runner.py:225} INFO - Task exited with return code 1
[2023-08-07T04:36:37.202+0000] {taskinstance.py:2653} INFO - 0 downstream tasks scheduled from follow-on schedule check
