[2023-08-07T04:53:44.308+0000] {taskinstance.py:1103} INFO - Dependencies all met for dep_context=non-requeueable deps ti=<TaskInstance: perform_s3_tasks.load_files_into_bucket manual__2023-08-07T04:48:59.150134+00:00 [queued]>
[2023-08-07T04:53:44.403+0000] {taskinstance.py:1103} INFO - Dependencies all met for dep_context=requeueable deps ti=<TaskInstance: perform_s3_tasks.load_files_into_bucket manual__2023-08-07T04:48:59.150134+00:00 [queued]>
[2023-08-07T04:53:44.408+0000] {taskinstance.py:1308} INFO - Starting attempt 4 of 9
[2023-08-07T04:53:44.693+0000] {taskinstance.py:1327} INFO - Executing <Task(LocalFilesystemToS3Operator): load_files_into_bucket> on 2023-08-07 04:48:59.150134+00:00
[2023-08-07T04:53:44.776+0000] {standard_task_runner.py:57} INFO - Started process 534 to run task
[2023-08-07T04:53:44.814+0000] {standard_task_runner.py:84} INFO - Running: ['***', 'tasks', 'run', 'perform_s3_tasks', 'load_files_into_bucket', 'manual__2023-08-07T04:48:59.150134+00:00', '--job-id', '18', '--raw', '--subdir', 'DAGS_FOLDER/s3_dag.py', '--cfg-path', '/tmp/tmp52zwkjnd']
[2023-08-07T04:53:44.821+0000] {standard_task_runner.py:85} INFO - Job 18: Subtask load_files_into_bucket
[2023-08-07T04:53:45.494+0000] {task_command.py:410} INFO - Running <TaskInstance: perform_s3_tasks.load_files_into_bucket manual__2023-08-07T04:48:59.150134+00:00 [running]> on host 95071573e7de
[2023-08-07T04:53:46.042+0000] {taskinstance.py:1547} INFO - Exporting env vars: AIRFLOW_CTX_DAG_OWNER='abhi' AIRFLOW_CTX_DAG_ID='perform_s3_tasks' AIRFLOW_CTX_TASK_ID='load_files_into_bucket' AIRFLOW_CTX_EXECUTION_DATE='2023-08-07T04:48:59.150134+00:00' AIRFLOW_CTX_TRY_NUMBER='4' AIRFLOW_CTX_DAG_RUN_ID='manual__2023-08-07T04:48:59.150134+00:00'
[2023-08-07T04:53:46.073+0000] {taskinstance.py:1824} ERROR - Task failed with exception
Traceback (most recent call last):
  File "/home/airflow/.local/lib/python3.7/site-packages/airflow/providers/amazon/aws/transfers/local_to_s3.py", line 98, in execute
    self.dest_bucket, self.dest_key, "dest_bucket", "dest_key"
  File "/home/airflow/.local/lib/python3.7/site-packages/airflow/providers/amazon/aws/hooks/s3.py", line 220, in get_s3_bucket_key
    return S3Hook.parse_s3_url(key)
  File "/home/airflow/.local/lib/python3.7/site-packages/airflow/providers/amazon/aws/hooks/s3.py", line 201, in parse_s3_url
    raise S3HookUriParseFailure(f'Please provide a bucket name using a valid format: "{s3url}"')
airflow.providers.amazon.aws.exceptions.S3HookUriParseFailure: Please provide a bucket name using a valid format: "/***-s3-fileloader"
[2023-08-07T04:53:46.093+0000] {taskinstance.py:1350} INFO - Marking task as UP_FOR_RETRY. dag_id=perform_s3_tasks, task_id=load_files_into_bucket, execution_date=20230807T044859, start_date=20230807T045344, end_date=20230807T045346
[2023-08-07T04:53:46.245+0000] {standard_task_runner.py:109} ERROR - Failed to execute job 18 for task load_files_into_bucket (Please provide a bucket name using a valid format: "/***-s3-fileloader"; 534)
[2023-08-07T04:53:46.292+0000] {local_task_job_runner.py:225} INFO - Task exited with return code 1
[2023-08-07T04:53:46.359+0000] {taskinstance.py:2653} INFO - 0 downstream tasks scheduled from follow-on schedule check
